{
 "cells": [
  {
   "cell_type": "markdown",
   "metadata": {},
   "source": [
    "### Test for lib retry"
   ]
  },
  {
   "cell_type": "code",
   "execution_count": 1,
   "metadata": {},
   "outputs": [],
   "source": [
    "import random\n",
    "from retrying import retry"
   ]
  },
  {
   "cell_type": "code",
   "execution_count": 12,
   "metadata": {},
   "outputs": [
    {
     "name": "stdout",
     "output_type": "stream",
     "text": [
      "It worked with number 9\n",
      "It worked with number 6\n",
      "It worked with number 2\n",
      "It worked with number 8\n",
      "It worked with number 2\n",
      "It worked with number 1\n",
      "Awesome sauce!\n"
     ]
    }
   ],
   "source": [
    "@retry\n",
    "def do_something_unreliable():\n",
    "    number = random.randint(0, 10)\n",
    "    print(f\"It worked with number {number}\")\n",
    "    if number > 1:\n",
    "        raise IOError(\"Broken sauce, everything is hosed!!!111one\")\n",
    "    else:\n",
    "        return \"Awesome sauce!\"\n",
    "\n",
    "print(do_something_unreliable())"
   ]
  },
  {
   "cell_type": "code",
   "execution_count": 51,
   "metadata": {},
   "outputs": [
    {
     "name": "stdout",
     "output_type": "stream",
     "text": [
      "initiating func()\n",
      "Try number 5\n",
      "retrying... with error found: \"A ValueError occurred with number: 5\"\n",
      "Try number 6\n",
      "retrying... with error found: \"An IOError occurred with number: 6\"\n",
      "Try number 7\n",
      "retrying... with error found: \"An IOError occurred with number: 7\"\n",
      "Try number 9\n",
      "retrying... with error found: \"An IOError occurred with number: 9\"\n",
      "Try number 9\n",
      "retrying... with error found: \"An IOError occurred with number: 9\"\n"
     ]
    },
    {
     "ename": "OSError",
     "evalue": "An IOError occurred with number: 9",
     "output_type": "error",
     "traceback": [
      "\u001b[0;31m---------------------------------------------------------------------------\u001b[0m",
      "\u001b[0;31mOSError\u001b[0m                                   Traceback (most recent call last)",
      "Cell \u001b[0;32mIn[51], line 31\u001b[0m\n\u001b[1;32m     29\u001b[0m func \u001b[38;5;241m=\u001b[39m might_io_error\n\u001b[1;32m     30\u001b[0m \u001b[38;5;28mprint\u001b[39m(\u001b[38;5;124m'\u001b[39m\u001b[38;5;124minitiating func()\u001b[39m\u001b[38;5;124m'\u001b[39m)\n\u001b[0;32m---> 31\u001b[0m \u001b[43mfunc\u001b[49m\u001b[43m(\u001b[49m\u001b[43m)\u001b[49m\n\u001b[1;32m     32\u001b[0m \u001b[38;5;28mprint\u001b[39m(\u001b[38;5;124m'\u001b[39m\u001b[38;5;124mfinished func()\u001b[39m\u001b[38;5;124m'\u001b[39m)\n",
      "File \u001b[0;32m~/Documentos/PROJETOS/ESTUDOS/SCRIPTS/.venv/lib/python3.12/site-packages/retrying.py:56\u001b[0m, in \u001b[0;36mretry.<locals>.wrap.<locals>.wrapped_f\u001b[0;34m(*args, **kw)\u001b[0m\n\u001b[1;32m     54\u001b[0m \u001b[38;5;129m@six\u001b[39m\u001b[38;5;241m.\u001b[39mwraps(f)\n\u001b[1;32m     55\u001b[0m \u001b[38;5;28;01mdef\u001b[39;00m \u001b[38;5;21mwrapped_f\u001b[39m(\u001b[38;5;241m*\u001b[39margs, \u001b[38;5;241m*\u001b[39m\u001b[38;5;241m*\u001b[39mkw):\n\u001b[0;32m---> 56\u001b[0m     \u001b[38;5;28;01mreturn\u001b[39;00m \u001b[43mRetrying\u001b[49m\u001b[43m(\u001b[49m\u001b[38;5;241;43m*\u001b[39;49m\u001b[43mdargs\u001b[49m\u001b[43m,\u001b[49m\u001b[43m \u001b[49m\u001b[38;5;241;43m*\u001b[39;49m\u001b[38;5;241;43m*\u001b[39;49m\u001b[43mdkw\u001b[49m\u001b[43m)\u001b[49m\u001b[38;5;241;43m.\u001b[39;49m\u001b[43mcall\u001b[49m\u001b[43m(\u001b[49m\u001b[43mf\u001b[49m\u001b[43m,\u001b[49m\u001b[43m \u001b[49m\u001b[38;5;241;43m*\u001b[39;49m\u001b[43margs\u001b[49m\u001b[43m,\u001b[49m\u001b[43m \u001b[49m\u001b[38;5;241;43m*\u001b[39;49m\u001b[38;5;241;43m*\u001b[39;49m\u001b[43mkw\u001b[49m\u001b[43m)\u001b[49m\n",
      "File \u001b[0;32m~/Documentos/PROJETOS/ESTUDOS/SCRIPTS/.venv/lib/python3.12/site-packages/retrying.py:266\u001b[0m, in \u001b[0;36mRetrying.call\u001b[0;34m(self, fn, *args, **kwargs)\u001b[0m\n\u001b[1;32m    263\u001b[0m \u001b[38;5;28;01mif\u001b[39;00m \u001b[38;5;28mself\u001b[39m\u001b[38;5;241m.\u001b[39mstop(attempt_number, delay_since_first_attempt_ms):\n\u001b[1;32m    264\u001b[0m     \u001b[38;5;28;01mif\u001b[39;00m \u001b[38;5;129;01mnot\u001b[39;00m \u001b[38;5;28mself\u001b[39m\u001b[38;5;241m.\u001b[39m_wrap_exception \u001b[38;5;129;01mand\u001b[39;00m attempt\u001b[38;5;241m.\u001b[39mhas_exception:\n\u001b[1;32m    265\u001b[0m         \u001b[38;5;66;03m# get() on an attempt with an exception should cause it to be raised, but raise just in case\u001b[39;00m\n\u001b[0;32m--> 266\u001b[0m         \u001b[38;5;28;01mraise\u001b[39;00m \u001b[43mattempt\u001b[49m\u001b[38;5;241;43m.\u001b[39;49m\u001b[43mget\u001b[49m\u001b[43m(\u001b[49m\u001b[43m)\u001b[49m\n\u001b[1;32m    267\u001b[0m     \u001b[38;5;28;01melse\u001b[39;00m:\n\u001b[1;32m    268\u001b[0m         \u001b[38;5;28;01mraise\u001b[39;00m RetryError(attempt)\n",
      "File \u001b[0;32m~/Documentos/PROJETOS/ESTUDOS/SCRIPTS/.venv/lib/python3.12/site-packages/retrying.py:301\u001b[0m, in \u001b[0;36mAttempt.get\u001b[0;34m(self, wrap_exception)\u001b[0m\n\u001b[1;32m    299\u001b[0m         \u001b[38;5;28;01mraise\u001b[39;00m RetryError(\u001b[38;5;28mself\u001b[39m)\n\u001b[1;32m    300\u001b[0m     \u001b[38;5;28;01melse\u001b[39;00m:\n\u001b[0;32m--> 301\u001b[0m         \u001b[43msix\u001b[49m\u001b[38;5;241;43m.\u001b[39;49m\u001b[43mreraise\u001b[49m\u001b[43m(\u001b[49m\u001b[38;5;28;43mself\u001b[39;49m\u001b[38;5;241;43m.\u001b[39;49m\u001b[43mvalue\u001b[49m\u001b[43m[\u001b[49m\u001b[38;5;241;43m0\u001b[39;49m\u001b[43m]\u001b[49m\u001b[43m,\u001b[49m\u001b[43m \u001b[49m\u001b[38;5;28;43mself\u001b[39;49m\u001b[38;5;241;43m.\u001b[39;49m\u001b[43mvalue\u001b[49m\u001b[43m[\u001b[49m\u001b[38;5;241;43m1\u001b[39;49m\u001b[43m]\u001b[49m\u001b[43m,\u001b[49m\u001b[43m \u001b[49m\u001b[38;5;28;43mself\u001b[39;49m\u001b[38;5;241;43m.\u001b[39;49m\u001b[43mvalue\u001b[49m\u001b[43m[\u001b[49m\u001b[38;5;241;43m2\u001b[39;49m\u001b[43m]\u001b[49m\u001b[43m)\u001b[49m\n\u001b[1;32m    302\u001b[0m \u001b[38;5;28;01melse\u001b[39;00m:\n\u001b[1;32m    303\u001b[0m     \u001b[38;5;28;01mreturn\u001b[39;00m \u001b[38;5;28mself\u001b[39m\u001b[38;5;241m.\u001b[39mvalue\n",
      "File \u001b[0;32m~/Documentos/PROJETOS/ESTUDOS/SCRIPTS/.venv/lib/python3.12/site-packages/six.py:719\u001b[0m, in \u001b[0;36mreraise\u001b[0;34m(tp, value, tb)\u001b[0m\n\u001b[1;32m    717\u001b[0m     \u001b[38;5;28;01mif\u001b[39;00m value\u001b[38;5;241m.\u001b[39m__traceback__ \u001b[38;5;129;01mis\u001b[39;00m \u001b[38;5;129;01mnot\u001b[39;00m tb:\n\u001b[1;32m    718\u001b[0m         \u001b[38;5;28;01mraise\u001b[39;00m value\u001b[38;5;241m.\u001b[39mwith_traceback(tb)\n\u001b[0;32m--> 719\u001b[0m     \u001b[38;5;28;01mraise\u001b[39;00m value\n\u001b[1;32m    720\u001b[0m \u001b[38;5;28;01mfinally\u001b[39;00m:\n\u001b[1;32m    721\u001b[0m     value \u001b[38;5;241m=\u001b[39m \u001b[38;5;28;01mNone\u001b[39;00m\n",
      "File \u001b[0;32m~/Documentos/PROJETOS/ESTUDOS/SCRIPTS/.venv/lib/python3.12/site-packages/retrying.py:251\u001b[0m, in \u001b[0;36mRetrying.call\u001b[0;34m(self, fn, *args, **kwargs)\u001b[0m\n\u001b[1;32m    248\u001b[0m     \u001b[38;5;28mself\u001b[39m\u001b[38;5;241m.\u001b[39m_before_attempts(attempt_number)\n\u001b[1;32m    250\u001b[0m \u001b[38;5;28;01mtry\u001b[39;00m:\n\u001b[0;32m--> 251\u001b[0m     attempt \u001b[38;5;241m=\u001b[39m Attempt(\u001b[43mfn\u001b[49m\u001b[43m(\u001b[49m\u001b[38;5;241;43m*\u001b[39;49m\u001b[43margs\u001b[49m\u001b[43m,\u001b[49m\u001b[43m \u001b[49m\u001b[38;5;241;43m*\u001b[39;49m\u001b[38;5;241;43m*\u001b[39;49m\u001b[43mkwargs\u001b[49m\u001b[43m)\u001b[49m, attempt_number, \u001b[38;5;28;01mFalse\u001b[39;00m)\n\u001b[1;32m    252\u001b[0m \u001b[38;5;28;01mexcept\u001b[39;00m:\n\u001b[1;32m    253\u001b[0m     tb \u001b[38;5;241m=\u001b[39m sys\u001b[38;5;241m.\u001b[39mexc_info()\n",
      "Cell \u001b[0;32mIn[51], line 24\u001b[0m, in \u001b[0;36mmight_io_error\u001b[0;34m()\u001b[0m\n\u001b[1;32m     22\u001b[0m     \u001b[38;5;28;01mraise\u001b[39;00m \u001b[38;5;167;01mException\u001b[39;00m(\u001b[38;5;124mf\u001b[39m\u001b[38;5;124m\"\u001b[39m\u001b[38;5;124mThis exception was not try with number: \u001b[39m\u001b[38;5;132;01m{\u001b[39;00mnumber\u001b[38;5;132;01m}\u001b[39;00m\u001b[38;5;124m\"\u001b[39m)\n\u001b[1;32m     23\u001b[0m \u001b[38;5;28;01mif\u001b[39;00m number \u001b[38;5;241m>\u001b[39m \u001b[38;5;241m5\u001b[39m:\n\u001b[0;32m---> 24\u001b[0m     \u001b[38;5;28;01mraise\u001b[39;00m \u001b[38;5;167;01mIOError\u001b[39;00m(\u001b[38;5;124mf\u001b[39m\u001b[38;5;124m\"\u001b[39m\u001b[38;5;124mAn IOError occurred with number: \u001b[39m\u001b[38;5;132;01m{\u001b[39;00mnumber\u001b[38;5;132;01m}\u001b[39;00m\u001b[38;5;124m\"\u001b[39m)\n\u001b[1;32m     25\u001b[0m \u001b[38;5;28;01mif\u001b[39;00m number \u001b[38;5;241m>\u001b[39m \u001b[38;5;241m1\u001b[39m:\n\u001b[1;32m     26\u001b[0m     \u001b[38;5;28;01mraise\u001b[39;00m \u001b[38;5;167;01mValueError\u001b[39;00m(\u001b[38;5;124mf\u001b[39m\u001b[38;5;124m\"\u001b[39m\u001b[38;5;124mA ValueError occurred with number: \u001b[39m\u001b[38;5;132;01m{\u001b[39;00mnumber\u001b[38;5;132;01m}\u001b[39;00m\u001b[38;5;124m\"\u001b[39m)\n",
      "\u001b[0;31mOSError\u001b[0m: An IOError occurred with number: 9"
     ]
    }
   ],
   "source": [
    "time_await = 3000\n",
    "stop_max_attempt_number = 5\n",
    "\n",
    "def retry_if_error(exception: Exception) -> bool:\n",
    "    \"\"\"\n",
    "    Return True if we should retry (in this case when it's an IOError or ValueError), False otherwise.\n",
    "\n",
    "    Parameters:\n",
    "    exception (Exception): The exception that occurred.\n",
    "\n",
    "    Returns:\n",
    "    bool: True if retry is needed, False otherwise.\n",
    "    \"\"\"\n",
    "    if isinstance(exception, (IOError, ValueError)):\n",
    "        print(f'retrying... with error found: \"{str(exception)}\"')\n",
    "        return True\n",
    "    print(f'Error type: {type(exception)}')\n",
    "    return False\n",
    "\n",
    "@retry(retry_on_exception=retry_if_error, wait_fixed=time_await, stop_max_attempt_number=stop_max_attempt_number)\n",
    "def might_io_error() -> None:\n",
    "    number = random.randint(0, 10)\n",
    "    print(f'Try number {number}')\n",
    "    if number == 0:\n",
    "        raise Exception(f\"This exception was not try with number: {number}\")\n",
    "    if number > 5:\n",
    "        raise IOError(f\"An IOError occurred with number: {number}\")\n",
    "    if number > 1:\n",
    "        raise ValueError(f\"A ValueError occurred with number: {number}\")\n",
    "    print(f\"finished func with number {number}\")\n",
    "\n",
    "func = might_io_error\n",
    "print('initiating func()')\n",
    "func()\n",
    "print('finished func()')"
   ]
  }
 ],
 "metadata": {
  "kernelspec": {
   "display_name": ".venv",
   "language": "python",
   "name": "python3"
  },
  "language_info": {
   "codemirror_mode": {
    "name": "ipython",
    "version": 3
   },
   "file_extension": ".py",
   "mimetype": "text/x-python",
   "name": "python",
   "nbconvert_exporter": "python",
   "pygments_lexer": "ipython3",
   "version": "3.12.0"
  }
 },
 "nbformat": 4,
 "nbformat_minor": 2
}
